Fri, 04 Mar 2016 11:08:34 seed.py[line:12] DEBUG This is debug message
Fri, 04 Mar 2016 11:08:34 seed.py[line:13] INFO This is info message
Fri, 04 Mar 2016 11:08:34 seed.py[line:14] WARNING This is warning message
Fri, 04 Mar 2016 11:08:34 seed.py[line:12] DEBUG This is debug message
Fri, 04 Mar 2016 11:08:34 seed.py[line:13] INFO This is info message
Fri, 04 Mar 2016 11:08:34 seed.py[line:14] WARNING This is warning message
Fri, 04 Mar 2016 11:08:34 seed.py[line:12] DEBUG This is debug message
Fri, 04 Mar 2016 11:08:34 seed.py[line:13] INFO This is info message
Fri, 04 Mar 2016 11:08:34 seed.py[line:14] WARNING This is warning message
Fri, 04 Mar 2016 11:08:35 seed.py[line:12] DEBUG This is debug message
Fri, 04 Mar 2016 11:08:35 seed.py[line:13] INFO This is info message
Fri, 04 Mar 2016 11:08:35 seed.py[line:14] WARNING This is warning message
Fri, 04 Mar 2016 11:08:35 seed.py[line:12] DEBUG This is debug message
Fri, 04 Mar 2016 11:08:35 seed.py[line:13] INFO This is info message
Fri, 04 Mar 2016 11:08:35 seed.py[line:14] WARNING This is warning message
Fri, 04 Mar 2016 11:08:35 seed.py[line:12] DEBUG This is debug message
Fri, 04 Mar 2016 11:08:35 seed.py[line:13] INFO This is info message
Fri, 04 Mar 2016 11:08:35 seed.py[line:14] WARNING This is warning message
Fri, 04 Mar 2016 11:08:35 seed.py[line:12] DEBUG This is debug message
Fri, 04 Mar 2016 11:08:35 seed.py[line:13] INFO This is info message
Fri, 04 Mar 2016 11:08:35 seed.py[line:14] WARNING This is warning message
Fri, 04 Mar 2016 11:08:35 seed.py[line:12] DEBUG This is debug message
Fri, 04 Mar 2016 11:08:35 seed.py[line:13] INFO This is info message
Fri, 04 Mar 2016 11:08:35 seed.py[line:14] WARNING This is warning message
Fri, 04 Mar 2016 11:31:21 seed.py[line:19] DEBUG This is debug message
Fri, 04 Mar 2016 11:32:15 seed.py[line:19] DEBUG This is debug message
Fri, 04 Mar 2016 11:32:21 seed.py[line:19] DEBUG This is debug message
Fri, 04 Mar 2016 11:32:39 seed.py[line:19] DEBUG This is debug message
Fri, 04 Mar 2016 11:32:40 seed.py[line:19] DEBUG This is debug message
Fri, 04 Mar 2016 11:32:40 seed.py[line:19] DEBUG This is debug message
Fri, 04 Mar 2016 11:32:40 seed.py[line:19] DEBUG This is debug message
Fri, 04 Mar 2016 11:32:40 seed.py[line:19] DEBUG This is debug message
Fri, 04 Mar 2016 11:32:40 seed.py[line:19] DEBUG This is debug message
Fri, 04 Mar 2016 11:32:52 seed.py[line:19] DEBUG This is debug message
Fri, 04 Mar 2016 11:32:53 seed.py[line:19] DEBUG This is debug message
Fri, 04 Mar 2016 11:32:53 seed.py[line:19] DEBUG This is debug message
Fri, 04 Mar 2016 11:32:53 seed.py[line:19] DEBUG This is debug message
Fri, 04 Mar 2016 11:32:54 seed.py[line:19] DEBUG This is debug message
Fri, 04 Mar 2016 11:32:54 seed.py[line:19] DEBUG This is debug message
Fri, 04 Mar 2016 11:32:54 seed.py[line:19] DEBUG This is debug message
Fri, 04 Mar 2016 11:32:54 seed.py[line:19] DEBUG This is debug message
Fri, 04 Mar 2016 11:32:55 seed.py[line:19] DEBUG This is debug message
Fri, 04 Mar 2016 11:32:55 seed.py[line:19] DEBUG This is debug message
Fri, 04 Mar 2016 11:32:55 seed.py[line:19] DEBUG This is debug message
Fri, 04 Mar 2016 11:32:55 seed.py[line:19] DEBUG This is debug message
Fri, 04 Mar 2016 12:34:06 seed.py[line:19] DEBUG This is debug message
Fri, 04 Mar 2016 12:34:06 seed.py[line:19] DEBUG This is debug message
Fri, 04 Mar 2016 12:34:07 seed.py[line:19] DEBUG This is debug message
Fri, 04 Mar 2016 12:34:07 seed.py[line:19] DEBUG This is debug message
Fri, 04 Mar 2016 12:34:07 seed.py[line:19] DEBUG This is debug message
Fri, 04 Mar 2016 12:34:08 seed.py[line:19] DEBUG This is debug message
Fri, 04 Mar 2016 12:34:08 seed.py[line:19] DEBUG This is debug message
Fri, 04 Mar 2016 12:34:08 seed.py[line:19] DEBUG This is debug message
Fri, 04 Mar 2016 12:34:08 seed.py[line:19] DEBUG This is debug message
Fri, 04 Mar 2016 12:34:08 seed.py[line:19] DEBUG This is debug message
Fri, 04 Mar 2016 12:42:27 handler.py[line:64] ERROR Traceback (most recent call last):
  File "C:\Users\U6036458\Documents\GitHub\Tornado-Seed\handler.py", line 44, in write_error
    if isinstance(e, exceptions.HTTPAPIError):
AttributeError: 'module' object has no attribute 'HTTPAPIError'

Fri, 04 Mar 2016 12:43:59 handler.py[line:64] ERROR Traceback (most recent call last):
  File "C:\Users\U6036458\Documents\GitHub\Tornado-Seed\handler.py", line 44, in write_error
    if isinstance(e, exceptions.HTTPAPIError):
AttributeError: 'module' object has no attribute 'HTTPAPIError'

Fri, 04 Mar 2016 12:48:37 handler.py[line:64] ERROR Traceback (most recent call last):
  File "C:\Users\U6036458\Documents\GitHub\Tornado-Seed\handler.py", line 44, in write_error
    if isinstance(e, exceptions.HTTPAPIError):
AttributeError: 'module' object has no attribute 'HTTPAPIError'

Fri, 04 Mar 2016 12:48:39 handler.py[line:64] ERROR Traceback (most recent call last):
  File "C:\Users\U6036458\Documents\GitHub\Tornado-Seed\handler.py", line 44, in write_error
    if isinstance(e, exceptions.HTTPAPIError):
AttributeError: 'module' object has no attribute 'HTTPAPIError'

Fri, 04 Mar 2016 12:48:39 handler.py[line:64] ERROR Traceback (most recent call last):
  File "C:\Users\U6036458\Documents\GitHub\Tornado-Seed\handler.py", line 44, in write_error
    if isinstance(e, exceptions.HTTPAPIError):
AttributeError: 'module' object has no attribute 'HTTPAPIError'

Fri, 04 Mar 2016 12:48:40 handler.py[line:64] ERROR Traceback (most recent call last):
  File "C:\Users\U6036458\Documents\GitHub\Tornado-Seed\handler.py", line 44, in write_error
    if isinstance(e, exceptions.HTTPAPIError):
AttributeError: 'module' object has no attribute 'HTTPAPIError'

Fri, 04 Mar 2016 12:48:40 handler.py[line:64] ERROR Traceback (most recent call last):
  File "C:\Users\U6036458\Documents\GitHub\Tornado-Seed\handler.py", line 44, in write_error
    if isinstance(e, exceptions.HTTPAPIError):
AttributeError: 'module' object has no attribute 'HTTPAPIError'

Fri, 04 Mar 2016 12:48:40 handler.py[line:64] ERROR Traceback (most recent call last):
  File "C:\Users\U6036458\Documents\GitHub\Tornado-Seed\handler.py", line 44, in write_error
    if isinstance(e, exceptions.HTTPAPIError):
AttributeError: 'module' object has no attribute 'HTTPAPIError'

Fri, 04 Mar 2016 12:48:40 handler.py[line:64] ERROR Traceback (most recent call last):
  File "C:\Users\U6036458\Documents\GitHub\Tornado-Seed\handler.py", line 44, in write_error
    if isinstance(e, exceptions.HTTPAPIError):
AttributeError: 'module' object has no attribute 'HTTPAPIError'

Fri, 04 Mar 2016 12:49:41 handler.py[line:64] ERROR Traceback (most recent call last):
  File "C:\Users\U6036458\Documents\GitHub\Tornado-Seed\handler.py", line 44, in write_error
    if isinstance(e, exceptions.HTTPAPIError):
AttributeError: 'module' object has no attribute 'HTTPAPIError'

Fri, 04 Mar 2016 12:59:35 handler.py[line:63] ERROR Traceback (most recent call last):
  File "C:\Users\U6036458\Documents\GitHub\Tornado-Seed\handler.py", line 48, in write_error
    e = APIError(500)
  File "C:\Users\U6036458\Documents\GitHub\Tornado-Seed\handler.py", line 88, in __init__
    super(HTTPAPIError, self).__init__(int(status_code), log_message, *args)
NameError: global name 'HTTPAPIError' is not defined

Fri, 04 Mar 2016 12:59:37 handler.py[line:63] ERROR Traceback (most recent call last):
  File "C:\Users\U6036458\Documents\GitHub\Tornado-Seed\handler.py", line 48, in write_error
    e = APIError(500)
  File "C:\Users\U6036458\Documents\GitHub\Tornado-Seed\handler.py", line 88, in __init__
    super(HTTPAPIError, self).__init__(int(status_code), log_message, *args)
NameError: global name 'HTTPAPIError' is not defined

Fri, 04 Mar 2016 12:59:37 handler.py[line:63] ERROR Traceback (most recent call last):
  File "C:\Users\U6036458\Documents\GitHub\Tornado-Seed\handler.py", line 48, in write_error
    e = APIError(500)
  File "C:\Users\U6036458\Documents\GitHub\Tornado-Seed\handler.py", line 88, in __init__
    super(HTTPAPIError, self).__init__(int(status_code), log_message, *args)
NameError: global name 'HTTPAPIError' is not defined

Fri, 04 Mar 2016 12:59:38 handler.py[line:63] ERROR Traceback (most recent call last):
  File "C:\Users\U6036458\Documents\GitHub\Tornado-Seed\handler.py", line 48, in write_error
    e = APIError(500)
  File "C:\Users\U6036458\Documents\GitHub\Tornado-Seed\handler.py", line 88, in __init__
    super(HTTPAPIError, self).__init__(int(status_code), log_message, *args)
NameError: global name 'HTTPAPIError' is not defined

Fri, 04 Mar 2016 12:59:38 handler.py[line:63] ERROR Traceback (most recent call last):
  File "C:\Users\U6036458\Documents\GitHub\Tornado-Seed\handler.py", line 48, in write_error
    e = APIError(500)
  File "C:\Users\U6036458\Documents\GitHub\Tornado-Seed\handler.py", line 88, in __init__
    super(HTTPAPIError, self).__init__(int(status_code), log_message, *args)
NameError: global name 'HTTPAPIError' is not defined

Fri, 04 Mar 2016 12:59:38 handler.py[line:63] ERROR Traceback (most recent call last):
  File "C:\Users\U6036458\Documents\GitHub\Tornado-Seed\handler.py", line 48, in write_error
    e = APIError(500)
  File "C:\Users\U6036458\Documents\GitHub\Tornado-Seed\handler.py", line 88, in __init__
    super(HTTPAPIError, self).__init__(int(status_code), log_message, *args)
NameError: global name 'HTTPAPIError' is not defined

Fri, 04 Mar 2016 12:59:39 handler.py[line:63] ERROR Traceback (most recent call last):
  File "C:\Users\U6036458\Documents\GitHub\Tornado-Seed\handler.py", line 48, in write_error
    e = APIError(500)
  File "C:\Users\U6036458\Documents\GitHub\Tornado-Seed\handler.py", line 88, in __init__
    super(HTTPAPIError, self).__init__(int(status_code), log_message, *args)
NameError: global name 'HTTPAPIError' is not defined

Fri, 04 Mar 2016 12:59:39 handler.py[line:63] ERROR Traceback (most recent call last):
  File "C:\Users\U6036458\Documents\GitHub\Tornado-Seed\handler.py", line 48, in write_error
    e = APIError(500)
  File "C:\Users\U6036458\Documents\GitHub\Tornado-Seed\handler.py", line 88, in __init__
    super(HTTPAPIError, self).__init__(int(status_code), log_message, *args)
NameError: global name 'HTTPAPIError' is not defined

Fri, 04 Mar 2016 12:59:39 handler.py[line:63] ERROR Traceback (most recent call last):
  File "C:\Users\U6036458\Documents\GitHub\Tornado-Seed\handler.py", line 48, in write_error
    e = APIError(500)
  File "C:\Users\U6036458\Documents\GitHub\Tornado-Seed\handler.py", line 88, in __init__
    super(HTTPAPIError, self).__init__(int(status_code), log_message, *args)
NameError: global name 'HTTPAPIError' is not defined

Fri, 04 Mar 2016 12:59:39 handler.py[line:63] ERROR Traceback (most recent call last):
  File "C:\Users\U6036458\Documents\GitHub\Tornado-Seed\handler.py", line 48, in write_error
    e = APIError(500)
  File "C:\Users\U6036458\Documents\GitHub\Tornado-Seed\handler.py", line 88, in __init__
    super(HTTPAPIError, self).__init__(int(status_code), log_message, *args)
NameError: global name 'HTTPAPIError' is not defined

Fri, 04 Mar 2016 13:04:27 handler.py[line:63] ERROR Traceback (most recent call last):
  File "C:\Users\U6036458\Documents\GitHub\Tornado-Seed\handler.py", line 48, in write_error
    e = APIError(500)
  File "C:\Users\U6036458\Documents\GitHub\Tornado-Seed\handler.py", line 88, in __init__
    super(HTTPAPIError, self).__init__(int(status_code), log_message, *args)
NameError: global name 'HTTPAPIError' is not defined

Fri, 04 Mar 2016 13:32:28 seed.py[line:14] DEBUG This is debug message
Fri, 04 Mar 2016 13:32:28 seed.py[line:15] WARNING This is warning message
Fri, 04 Mar 2016 17:45:29 seed.py[line:14] DEBUG This is debug message
Fri, 04 Mar 2016 17:45:29 seed.py[line:15] WARNING This is warning message
Fri, 04 Mar 2016 17:45:29 seed.py[line:14] DEBUG This is debug message
Fri, 04 Mar 2016 17:45:29 seed.py[line:15] WARNING This is warning message
Fri, 04 Mar 2016 17:45:30 seed.py[line:14] DEBUG This is debug message
Fri, 04 Mar 2016 17:45:30 seed.py[line:15] WARNING This is warning message
Fri, 04 Mar 2016 17:45:30 seed.py[line:14] DEBUG This is debug message
Fri, 04 Mar 2016 17:45:30 seed.py[line:15] WARNING This is warning message
Fri, 04 Mar 2016 17:45:31 seed.py[line:14] DEBUG This is debug message
Fri, 04 Mar 2016 17:45:31 seed.py[line:15] WARNING This is warning message
Fri, 04 Mar 2016 17:45:31 seed.py[line:14] DEBUG This is debug message
Fri, 04 Mar 2016 17:45:31 seed.py[line:15] WARNING This is warning message
Mon, 07 Mar 2016 15:17:05 seed.py[line:14] DEBUG This is debug message
Mon, 07 Mar 2016 15:17:05 seed.py[line:15] WARNING This is warning message
Mon, 07 Mar 2016 15:19:01 seed.py[line:14] DEBUG This is debug message
Mon, 07 Mar 2016 15:19:01 seed.py[line:15] WARNING This is warning message
Mon, 07 Mar 2016 15:24:10 seed.py[line:14] DEBUG This is debug message
Mon, 07 Mar 2016 15:24:10 seed.py[line:15] WARNING This is warning message
Mon, 07 Mar 2016 15:24:10 seed.py[line:14] DEBUG This is debug message
Mon, 07 Mar 2016 15:24:10 seed.py[line:15] WARNING This is warning message
Mon, 07 Mar 2016 15:24:10 seed.py[line:14] DEBUG This is debug message
Mon, 07 Mar 2016 15:24:10 seed.py[line:15] WARNING This is warning message
Mon, 07 Mar 2016 15:24:11 seed.py[line:14] DEBUG This is debug message
Mon, 07 Mar 2016 15:24:11 seed.py[line:15] WARNING This is warning message
Mon, 07 Mar 2016 15:24:11 seed.py[line:14] DEBUG This is debug message
Mon, 07 Mar 2016 15:24:11 seed.py[line:15] WARNING This is warning message
Mon, 07 Mar 2016 17:43:38 callback.py[line:164] DEBUG Added: {'callback': <bound method TornadoConnection._on_connection_error of <pika.adapters.tornado_connection.TornadoConnection object at 0x00000000042EC4A8>>, 'only': None, 'one_shot': False, 'arguments': None}
Mon, 07 Mar 2016 17:43:38 callback.py[line:164] DEBUG Added: {'callback': <functools.partial object at 0x00000000042EB818>, 'only': None, 'one_shot': False, 'arguments': None}
Mon, 07 Mar 2016 17:43:38 callback.py[line:164] DEBUG Added: {'callback': <functools.partial object at 0x00000000042EB868>, 'only': None, 'one_shot': False, 'arguments': None}
Mon, 07 Mar 2016 17:43:38 callback.py[line:164] DEBUG Added: {'callback': <bound method TornadoConnection._on_connection_start of <pika.adapters.tornado_connection.TornadoConnection object at 0x00000000042EC4A8>>, 'only': None, 'one_shot': True, 'arguments': None, 'calls': 1}
Mon, 07 Mar 2016 17:43:38 base_connection.py[line:212] INFO Connecting to 127.0.0.1:5672
Mon, 07 Mar 2016 17:43:38 base_connection.py[line:221] ERROR Connection to 127.0.0.1:5672 failed: timeout
Mon, 07 Mar 2016 17:43:38 base_connection.py[line:212] INFO Connecting to ::1:5672
Mon, 07 Mar 2016 17:43:39 base_connection.py[line:221] ERROR Connection to ::1:5672 failed: timeout
Mon, 07 Mar 2016 17:43:39 connection.py[line:750] WARNING Could not connect, 0 attempts left
Mon, 07 Mar 2016 17:43:39 callback.py[line:220] DEBUG Processing 0:_on_connection_error
Mon, 07 Mar 2016 17:43:39 callback.py[line:234] DEBUG Calling <bound method TornadoConnection._on_connection_error of <pika.adapters.tornado_connection.TornadoConnection object at 0x00000000042EC4A8>> for "0:_on_connection_error"
Mon, 07 Mar 2016 17:43:39 callback.py[line:239] ERROR Calling <bound method TornadoConnection._on_connection_error of <pika.adapters.tornado_connection.TornadoConnection object at 0x00000000042EC4A8>> for "0:_on_connection_error" failed
Traceback (most recent call last):
  File "C:\Python27\lib\site-packages\pika\callback.py", line 236, in process
    callback(*args, **keywords)
  File "C:\Python27\lib\site-packages\pika\connection.py", line 1265, in _on_connection_error
    self.params.connection_attempts)
AMQPConnectionError: Connection to ::1:5672 failed: timeout
Mon, 07 Mar 2016 17:43:39 connection.py[line:54] INFO Retrying to connect in 2 seconds
Mon, 07 Mar 2016 17:43:41 callback.py[line:164] DEBUG Added: {'callback': <bound method TornadoConnection._on_connection_error of <pika.adapters.tornado_connection.TornadoConnection object at 0x00000000043387B8>>, 'only': None, 'one_shot': False, 'arguments': None}
Mon, 07 Mar 2016 17:43:41 callback.py[line:164] DEBUG Added: {'callback': <functools.partial object at 0x0000000002850228>, 'only': None, 'one_shot': False, 'arguments': None}
Mon, 07 Mar 2016 17:43:41 callback.py[line:164] DEBUG Added: {'callback': <functools.partial object at 0x00000000043456D8>, 'only': None, 'one_shot': False, 'arguments': None}
Mon, 07 Mar 2016 17:43:41 callback.py[line:164] DEBUG Added: {'callback': <bound method TornadoConnection._on_connection_start of <pika.adapters.tornado_connection.TornadoConnection object at 0x00000000043387B8>>, 'only': None, 'one_shot': True, 'arguments': None, 'calls': 1}
Mon, 07 Mar 2016 17:43:41 base_connection.py[line:212] INFO Connecting to 127.0.0.1:5672
Mon, 07 Mar 2016 17:43:41 base_connection.py[line:221] ERROR Connection to 127.0.0.1:5672 failed: timeout
Mon, 07 Mar 2016 17:43:41 base_connection.py[line:212] INFO Connecting to ::1:5672
Mon, 07 Mar 2016 17:43:41 base_connection.py[line:221] ERROR Connection to ::1:5672 failed: timeout
Mon, 07 Mar 2016 17:43:41 connection.py[line:750] WARNING Could not connect, 0 attempts left
Mon, 07 Mar 2016 17:43:41 callback.py[line:220] DEBUG Processing 0:_on_connection_error
Mon, 07 Mar 2016 17:43:41 callback.py[line:234] DEBUG Calling <bound method TornadoConnection._on_connection_error of <pika.adapters.tornado_connection.TornadoConnection object at 0x00000000043387B8>> for "0:_on_connection_error"
Mon, 07 Mar 2016 17:43:41 callback.py[line:239] ERROR Calling <bound method TornadoConnection._on_connection_error of <pika.adapters.tornado_connection.TornadoConnection object at 0x00000000043387B8>> for "0:_on_connection_error" failed
Traceback (most recent call last):
  File "C:\Python27\lib\site-packages\pika\callback.py", line 236, in process
    callback(*args, **keywords)
  File "C:\Python27\lib\site-packages\pika\connection.py", line 1265, in _on_connection_error
    self.params.connection_attempts)
AMQPConnectionError: Connection to ::1:5672 failed: timeout
Mon, 07 Mar 2016 17:43:41 connection.py[line:54] INFO Retrying to connect in 2 seconds
Mon, 07 Mar 2016 17:43:43 callback.py[line:164] DEBUG Added: {'callback': <bound method TornadoConnection._on_connection_error of <pika.adapters.tornado_connection.TornadoConnection object at 0x0000000004338940>>, 'only': None, 'one_shot': False, 'arguments': None}
Mon, 07 Mar 2016 17:43:43 callback.py[line:164] DEBUG Added: {'callback': <functools.partial object at 0x000000000433E318>, 'only': None, 'one_shot': False, 'arguments': None}
Mon, 07 Mar 2016 17:43:43 callback.py[line:164] DEBUG Added: {'callback': <functools.partial object at 0x0000000004345688>, 'only': None, 'one_shot': False, 'arguments': None}
Mon, 07 Mar 2016 17:43:43 callback.py[line:164] DEBUG Added: {'callback': <bound method TornadoConnection._on_connection_start of <pika.adapters.tornado_connection.TornadoConnection object at 0x0000000004338940>>, 'only': None, 'one_shot': True, 'arguments': None, 'calls': 1}
Mon, 07 Mar 2016 17:43:43 base_connection.py[line:212] INFO Connecting to 127.0.0.1:5672
Mon, 07 Mar 2016 17:43:43 base_connection.py[line:221] ERROR Connection to 127.0.0.1:5672 failed: timeout
Mon, 07 Mar 2016 17:43:43 base_connection.py[line:212] INFO Connecting to ::1:5672
Mon, 07 Mar 2016 17:43:44 base_connection.py[line:221] ERROR Connection to ::1:5672 failed: timeout
Mon, 07 Mar 2016 17:43:44 connection.py[line:750] WARNING Could not connect, 0 attempts left
Mon, 07 Mar 2016 17:43:44 callback.py[line:220] DEBUG Processing 0:_on_connection_error
Mon, 07 Mar 2016 17:43:44 callback.py[line:234] DEBUG Calling <bound method TornadoConnection._on_connection_error of <pika.adapters.tornado_connection.TornadoConnection object at 0x0000000004338940>> for "0:_on_connection_error"
Mon, 07 Mar 2016 17:43:44 callback.py[line:239] ERROR Calling <bound method TornadoConnection._on_connection_error of <pika.adapters.tornado_connection.TornadoConnection object at 0x0000000004338940>> for "0:_on_connection_error" failed
Traceback (most recent call last):
  File "C:\Python27\lib\site-packages\pika\callback.py", line 236, in process
    callback(*args, **keywords)
  File "C:\Python27\lib\site-packages\pika\connection.py", line 1265, in _on_connection_error
    self.params.connection_attempts)
AMQPConnectionError: Connection to ::1:5672 failed: timeout
Mon, 07 Mar 2016 17:43:44 connection.py[line:54] INFO Retrying to connect in 2 seconds
Mon, 07 Mar 2016 17:43:46 callback.py[line:164] DEBUG Added: {'callback': <bound method TornadoConnection._on_connection_error of <pika.adapters.tornado_connection.TornadoConnection object at 0x0000000004338A20>>, 'only': None, 'one_shot': False, 'arguments': None}
Mon, 07 Mar 2016 17:43:46 callback.py[line:164] DEBUG Added: {'callback': <functools.partial object at 0x000000000433E3B8>, 'only': None, 'one_shot': False, 'arguments': None}
Mon, 07 Mar 2016 17:43:46 callback.py[line:164] DEBUG Added: {'callback': <functools.partial object at 0x00000000043457C8>, 'only': None, 'one_shot': False, 'arguments': None}
Mon, 07 Mar 2016 17:43:46 callback.py[line:164] DEBUG Added: {'callback': <bound method TornadoConnection._on_connection_start of <pika.adapters.tornado_connection.TornadoConnection object at 0x0000000004338A20>>, 'only': None, 'one_shot': True, 'arguments': None, 'calls': 1}
Mon, 07 Mar 2016 17:43:46 base_connection.py[line:212] INFO Connecting to 127.0.0.1:5672
Mon, 07 Mar 2016 17:43:46 base_connection.py[line:221] ERROR Connection to 127.0.0.1:5672 failed: timeout
Mon, 07 Mar 2016 17:43:46 base_connection.py[line:212] INFO Connecting to ::1:5672
Mon, 07 Mar 2016 17:43:46 base_connection.py[line:221] ERROR Connection to ::1:5672 failed: timeout
Mon, 07 Mar 2016 17:43:46 connection.py[line:750] WARNING Could not connect, 0 attempts left
Mon, 07 Mar 2016 17:43:46 callback.py[line:220] DEBUG Processing 0:_on_connection_error
Mon, 07 Mar 2016 17:43:46 callback.py[line:234] DEBUG Calling <bound method TornadoConnection._on_connection_error of <pika.adapters.tornado_connection.TornadoConnection object at 0x0000000004338A20>> for "0:_on_connection_error"
Mon, 07 Mar 2016 17:43:46 callback.py[line:239] ERROR Calling <bound method TornadoConnection._on_connection_error of <pika.adapters.tornado_connection.TornadoConnection object at 0x0000000004338A20>> for "0:_on_connection_error" failed
Traceback (most recent call last):
  File "C:\Python27\lib\site-packages\pika\callback.py", line 236, in process
    callback(*args, **keywords)
  File "C:\Python27\lib\site-packages\pika\connection.py", line 1265, in _on_connection_error
    self.params.connection_attempts)
AMQPConnectionError: Connection to ::1:5672 failed: timeout
Mon, 07 Mar 2016 17:43:46 connection.py[line:54] INFO Retrying to connect in 2 seconds
Mon, 07 Mar 2016 17:43:48 callback.py[line:164] DEBUG Added: {'callback': <bound method TornadoConnection._on_connection_error of <pika.adapters.tornado_connection.TornadoConnection object at 0x0000000004338B38>>, 'only': None, 'one_shot': False, 'arguments': None}
Mon, 07 Mar 2016 17:43:48 callback.py[line:164] DEBUG Added: {'callback': <functools.partial object at 0x0000000004345818>, 'only': None, 'one_shot': False, 'arguments': None}
Mon, 07 Mar 2016 17:43:48 callback.py[line:164] DEBUG Added: {'callback': <functools.partial object at 0x0000000004345868>, 'only': None, 'one_shot': False, 'arguments': None}
Mon, 07 Mar 2016 17:43:48 callback.py[line:164] DEBUG Added: {'callback': <bound method TornadoConnection._on_connection_start of <pika.adapters.tornado_connection.TornadoConnection object at 0x0000000004338B38>>, 'only': None, 'one_shot': True, 'arguments': None, 'calls': 1}
Mon, 07 Mar 2016 17:43:48 base_connection.py[line:212] INFO Connecting to 127.0.0.1:5672
Mon, 07 Mar 2016 17:43:48 base_connection.py[line:221] ERROR Connection to 127.0.0.1:5672 failed: timeout
Mon, 07 Mar 2016 17:43:48 base_connection.py[line:212] INFO Connecting to ::1:5672
Mon, 07 Mar 2016 17:43:49 base_connection.py[line:221] ERROR Connection to ::1:5672 failed: timeout
Mon, 07 Mar 2016 17:43:49 connection.py[line:750] WARNING Could not connect, 0 attempts left
Mon, 07 Mar 2016 17:43:49 callback.py[line:220] DEBUG Processing 0:_on_connection_error
Mon, 07 Mar 2016 17:43:49 callback.py[line:234] DEBUG Calling <bound method TornadoConnection._on_connection_error of <pika.adapters.tornado_connection.TornadoConnection object at 0x0000000004338B38>> for "0:_on_connection_error"
Mon, 07 Mar 2016 17:43:49 callback.py[line:239] ERROR Calling <bound method TornadoConnection._on_connection_error of <pika.adapters.tornado_connection.TornadoConnection object at 0x0000000004338B38>> for "0:_on_connection_error" failed
Traceback (most recent call last):
  File "C:\Python27\lib\site-packages\pika\callback.py", line 236, in process
    callback(*args, **keywords)
  File "C:\Python27\lib\site-packages\pika\connection.py", line 1265, in _on_connection_error
    self.params.connection_attempts)
AMQPConnectionError: Connection to ::1:5672 failed: timeout
Mon, 07 Mar 2016 17:43:49 connection.py[line:54] INFO Retrying to connect in 2 seconds
Mon, 07 Mar 2016 17:43:51 callback.py[line:164] DEBUG Added: {'callback': <bound method TornadoConnection._on_connection_error of <pika.adapters.tornado_connection.TornadoConnection object at 0x0000000004338C50>>, 'only': None, 'one_shot': False, 'arguments': None}
Mon, 07 Mar 2016 17:43:51 callback.py[line:164] DEBUG Added: {'callback': <functools.partial object at 0x00000000043458B8>, 'only': None, 'one_shot': False, 'arguments': None}
Mon, 07 Mar 2016 17:43:51 callback.py[line:164] DEBUG Added: {'callback': <functools.partial object at 0x0000000004345908>, 'only': None, 'one_shot': False, 'arguments': None}
Mon, 07 Mar 2016 17:43:51 callback.py[line:164] DEBUG Added: {'callback': <bound method TornadoConnection._on_connection_start of <pika.adapters.tornado_connection.TornadoConnection object at 0x0000000004338C50>>, 'only': None, 'one_shot': True, 'arguments': None, 'calls': 1}
Mon, 07 Mar 2016 17:43:51 base_connection.py[line:212] INFO Connecting to 127.0.0.1:5672
Mon, 07 Mar 2016 17:43:51 base_connection.py[line:221] ERROR Connection to 127.0.0.1:5672 failed: timeout
Mon, 07 Mar 2016 17:43:51 base_connection.py[line:212] INFO Connecting to ::1:5672
Mon, 07 Mar 2016 17:43:51 base_connection.py[line:221] ERROR Connection to ::1:5672 failed: timeout
Mon, 07 Mar 2016 17:43:51 connection.py[line:750] WARNING Could not connect, 0 attempts left
Mon, 07 Mar 2016 17:43:51 callback.py[line:220] DEBUG Processing 0:_on_connection_error
Mon, 07 Mar 2016 17:43:51 callback.py[line:234] DEBUG Calling <bound method TornadoConnection._on_connection_error of <pika.adapters.tornado_connection.TornadoConnection object at 0x0000000004338C50>> for "0:_on_connection_error"
Mon, 07 Mar 2016 17:43:51 callback.py[line:239] ERROR Calling <bound method TornadoConnection._on_connection_error of <pika.adapters.tornado_connection.TornadoConnection object at 0x0000000004338C50>> for "0:_on_connection_error" failed
Traceback (most recent call last):
  File "C:\Python27\lib\site-packages\pika\callback.py", line 236, in process
    callback(*args, **keywords)
  File "C:\Python27\lib\site-packages\pika\connection.py", line 1265, in _on_connection_error
    self.params.connection_attempts)
AMQPConnectionError: Connection to ::1:5672 failed: timeout
Mon, 07 Mar 2016 17:43:51 connection.py[line:54] INFO Retrying to connect in 2 seconds
Mon, 07 Mar 2016 17:43:53 callback.py[line:164] DEBUG Added: {'callback': <bound method TornadoConnection._on_connection_error of <pika.adapters.tornado_connection.TornadoConnection object at 0x0000000004338D68>>, 'only': None, 'one_shot': False, 'arguments': None}
Mon, 07 Mar 2016 17:43:53 callback.py[line:164] DEBUG Added: {'callback': <functools.partial object at 0x0000000004345958>, 'only': None, 'one_shot': False, 'arguments': None}
Mon, 07 Mar 2016 17:43:53 callback.py[line:164] DEBUG Added: {'callback': <functools.partial object at 0x00000000043459A8>, 'only': None, 'one_shot': False, 'arguments': None}
Mon, 07 Mar 2016 17:43:53 callback.py[line:164] DEBUG Added: {'callback': <bound method TornadoConnection._on_connection_start of <pika.adapters.tornado_connection.TornadoConnection object at 0x0000000004338D68>>, 'only': None, 'one_shot': True, 'arguments': None, 'calls': 1}
Mon, 07 Mar 2016 17:43:53 base_connection.py[line:212] INFO Connecting to 127.0.0.1:5672
Mon, 07 Mar 2016 17:43:53 base_connection.py[line:221] ERROR Connection to 127.0.0.1:5672 failed: timeout
Mon, 07 Mar 2016 17:43:53 base_connection.py[line:212] INFO Connecting to ::1:5672
Mon, 07 Mar 2016 17:43:54 base_connection.py[line:221] ERROR Connection to ::1:5672 failed: timeout
Mon, 07 Mar 2016 17:43:54 connection.py[line:750] WARNING Could not connect, 0 attempts left
Mon, 07 Mar 2016 17:43:54 callback.py[line:220] DEBUG Processing 0:_on_connection_error
Mon, 07 Mar 2016 17:43:54 callback.py[line:234] DEBUG Calling <bound method TornadoConnection._on_connection_error of <pika.adapters.tornado_connection.TornadoConnection object at 0x0000000004338D68>> for "0:_on_connection_error"
Mon, 07 Mar 2016 17:43:54 callback.py[line:239] ERROR Calling <bound method TornadoConnection._on_connection_error of <pika.adapters.tornado_connection.TornadoConnection object at 0x0000000004338D68>> for "0:_on_connection_error" failed
Traceback (most recent call last):
  File "C:\Python27\lib\site-packages\pika\callback.py", line 236, in process
    callback(*args, **keywords)
  File "C:\Python27\lib\site-packages\pika\connection.py", line 1265, in _on_connection_error
    self.params.connection_attempts)
AMQPConnectionError: Connection to ::1:5672 failed: timeout
Mon, 07 Mar 2016 17:43:54 connection.py[line:54] INFO Retrying to connect in 2 seconds
Mon, 07 Mar 2016 17:43:56 callback.py[line:164] DEBUG Added: {'callback': <bound method TornadoConnection._on_connection_error of <pika.adapters.tornado_connection.TornadoConnection object at 0x0000000004338E80>>, 'only': None, 'one_shot': False, 'arguments': None}
Mon, 07 Mar 2016 17:43:56 callback.py[line:164] DEBUG Added: {'callback': <functools.partial object at 0x00000000043459F8>, 'only': None, 'one_shot': False, 'arguments': None}
Mon, 07 Mar 2016 17:43:56 callback.py[line:164] DEBUG Added: {'callback': <functools.partial object at 0x0000000004345A48>, 'only': None, 'one_shot': False, 'arguments': None}
Mon, 07 Mar 2016 17:43:56 callback.py[line:164] DEBUG Added: {'callback': <bound method TornadoConnection._on_connection_start of <pika.adapters.tornado_connection.TornadoConnection object at 0x0000000004338E80>>, 'only': None, 'one_shot': True, 'arguments': None, 'calls': 1}
Mon, 07 Mar 2016 17:43:56 base_connection.py[line:212] INFO Connecting to 127.0.0.1:5672
Mon, 07 Mar 2016 17:43:56 base_connection.py[line:221] ERROR Connection to 127.0.0.1:5672 failed: timeout
Mon, 07 Mar 2016 17:43:56 base_connection.py[line:212] INFO Connecting to ::1:5672
Mon, 07 Mar 2016 17:43:56 base_connection.py[line:221] ERROR Connection to ::1:5672 failed: timeout
Mon, 07 Mar 2016 17:43:56 connection.py[line:750] WARNING Could not connect, 0 attempts left
Mon, 07 Mar 2016 17:43:56 callback.py[line:220] DEBUG Processing 0:_on_connection_error
Mon, 07 Mar 2016 17:43:56 callback.py[line:234] DEBUG Calling <bound method TornadoConnection._on_connection_error of <pika.adapters.tornado_connection.TornadoConnection object at 0x0000000004338E80>> for "0:_on_connection_error"
Mon, 07 Mar 2016 17:43:56 callback.py[line:239] ERROR Calling <bound method TornadoConnection._on_connection_error of <pika.adapters.tornado_connection.TornadoConnection object at 0x0000000004338E80>> for "0:_on_connection_error" failed
Traceback (most recent call last):
  File "C:\Python27\lib\site-packages\pika\callback.py", line 236, in process
    callback(*args, **keywords)
  File "C:\Python27\lib\site-packages\pika\connection.py", line 1265, in _on_connection_error
    self.params.connection_attempts)
AMQPConnectionError: Connection to ::1:5672 failed: timeout
Mon, 07 Mar 2016 17:43:56 connection.py[line:54] INFO Retrying to connect in 2 seconds
Mon, 07 Mar 2016 17:43:58 callback.py[line:164] DEBUG Added: {'callback': <bound method TornadoConnection._on_connection_error of <pika.adapters.tornado_connection.TornadoConnection object at 0x00000000042EC4E0>>, 'only': None, 'one_shot': False, 'arguments': None}
Mon, 07 Mar 2016 17:43:58 callback.py[line:164] DEBUG Added: {'callback': <functools.partial object at 0x00000000042EB868>, 'only': None, 'one_shot': False, 'arguments': None}
Mon, 07 Mar 2016 17:43:58 callback.py[line:164] DEBUG Added: {'callback': <functools.partial object at 0x00000000042EB818>, 'only': None, 'one_shot': False, 'arguments': None}
Mon, 07 Mar 2016 17:43:58 callback.py[line:164] DEBUG Added: {'callback': <bound method TornadoConnection._on_connection_start of <pika.adapters.tornado_connection.TornadoConnection object at 0x00000000042EC4E0>>, 'only': None, 'one_shot': True, 'arguments': None, 'calls': 1}
Mon, 07 Mar 2016 17:43:58 base_connection.py[line:212] INFO Connecting to 127.0.0.1:5672
Mon, 07 Mar 2016 17:43:58 base_connection.py[line:221] ERROR Connection to 127.0.0.1:5672 failed: timeout
Mon, 07 Mar 2016 17:43:58 base_connection.py[line:212] INFO Connecting to ::1:5672
Mon, 07 Mar 2016 17:43:59 base_connection.py[line:221] ERROR Connection to ::1:5672 failed: timeout
Mon, 07 Mar 2016 17:43:59 connection.py[line:750] WARNING Could not connect, 0 attempts left
Mon, 07 Mar 2016 17:43:59 callback.py[line:220] DEBUG Processing 0:_on_connection_error
Mon, 07 Mar 2016 17:43:59 callback.py[line:234] DEBUG Calling <bound method TornadoConnection._on_connection_error of <pika.adapters.tornado_connection.TornadoConnection object at 0x00000000042EC4E0>> for "0:_on_connection_error"
Mon, 07 Mar 2016 17:43:59 callback.py[line:239] ERROR Calling <bound method TornadoConnection._on_connection_error of <pika.adapters.tornado_connection.TornadoConnection object at 0x00000000042EC4E0>> for "0:_on_connection_error" failed
Traceback (most recent call last):
  File "C:\Python27\lib\site-packages\pika\callback.py", line 236, in process
    callback(*args, **keywords)
  File "C:\Python27\lib\site-packages\pika\connection.py", line 1265, in _on_connection_error
    self.params.connection_attempts)
AMQPConnectionError: Connection to ::1:5672 failed: timeout
Mon, 07 Mar 2016 17:43:59 connection.py[line:54] INFO Retrying to connect in 2 seconds
Mon, 07 Mar 2016 17:44:01 callback.py[line:164] DEBUG Added: {'callback': <bound method TornadoConnection._on_connection_error of <pika.adapters.tornado_connection.TornadoConnection object at 0x0000000004338CC0>>, 'only': None, 'one_shot': False, 'arguments': None}
Mon, 07 Mar 2016 17:44:01 callback.py[line:164] DEBUG Added: {'callback': <functools.partial object at 0x0000000002850228>, 'only': None, 'one_shot': False, 'arguments': None}
Mon, 07 Mar 2016 17:44:01 callback.py[line:164] DEBUG Added: {'callback': <functools.partial object at 0x000000000433E3B8>, 'only': None, 'one_shot': False, 'arguments': None}
Mon, 07 Mar 2016 17:44:01 callback.py[line:164] DEBUG Added: {'callback': <bound method TornadoConnection._on_connection_start of <pika.adapters.tornado_connection.TornadoConnection object at 0x0000000004338CC0>>, 'only': None, 'one_shot': True, 'arguments': None, 'calls': 1}
Mon, 07 Mar 2016 17:44:01 base_connection.py[line:212] INFO Connecting to 127.0.0.1:5672
Mon, 07 Mar 2016 17:44:01 base_connection.py[line:221] ERROR Connection to 127.0.0.1:5672 failed: timeout
Mon, 07 Mar 2016 17:44:01 base_connection.py[line:212] INFO Connecting to ::1:5672
Mon, 07 Mar 2016 17:44:01 base_connection.py[line:221] ERROR Connection to ::1:5672 failed: timeout
Mon, 07 Mar 2016 17:44:01 connection.py[line:750] WARNING Could not connect, 0 attempts left
Mon, 07 Mar 2016 17:44:01 callback.py[line:220] DEBUG Processing 0:_on_connection_error
Mon, 07 Mar 2016 17:44:01 callback.py[line:234] DEBUG Calling <bound method TornadoConnection._on_connection_error of <pika.adapters.tornado_connection.TornadoConnection object at 0x0000000004338CC0>> for "0:_on_connection_error"
Mon, 07 Mar 2016 17:44:01 callback.py[line:239] ERROR Calling <bound method TornadoConnection._on_connection_error of <pika.adapters.tornado_connection.TornadoConnection object at 0x0000000004338CC0>> for "0:_on_connection_error" failed
Traceback (most recent call last):
  File "C:\Python27\lib\site-packages\pika\callback.py", line 236, in process
    callback(*args, **keywords)
  File "C:\Python27\lib\site-packages\pika\connection.py", line 1265, in _on_connection_error
    self.params.connection_attempts)
AMQPConnectionError: Connection to ::1:5672 failed: timeout
Mon, 07 Mar 2016 17:44:01 connection.py[line:54] INFO Retrying to connect in 2 seconds
Mon, 07 Mar 2016 17:44:03 callback.py[line:164] DEBUG Added: {'callback': <bound method TornadoConnection._on_connection_error of <pika.adapters.tornado_connection.TornadoConnection object at 0x0000000004338BA8>>, 'only': None, 'one_shot': False, 'arguments': None}
Mon, 07 Mar 2016 17:44:03 callback.py[line:164] DEBUG Added: {'callback': <functools.partial object at 0x000000000433E318>, 'only': None, 'one_shot': False, 'arguments': None}
Mon, 07 Mar 2016 17:44:03 callback.py[line:164] DEBUG Added: {'callback': <functools.partial object at 0x0000000004345A98>, 'only': None, 'one_shot': False, 'arguments': None}
Mon, 07 Mar 2016 17:44:03 callback.py[line:164] DEBUG Added: {'callback': <bound method TornadoConnection._on_connection_start of <pika.adapters.tornado_connection.TornadoConnection object at 0x0000000004338BA8>>, 'only': None, 'one_shot': True, 'arguments': None, 'calls': 1}
Mon, 07 Mar 2016 17:44:03 base_connection.py[line:212] INFO Connecting to 127.0.0.1:5672
Mon, 07 Mar 2016 17:44:03 base_connection.py[line:221] ERROR Connection to 127.0.0.1:5672 failed: timeout
Mon, 07 Mar 2016 17:44:03 base_connection.py[line:212] INFO Connecting to ::1:5672
Mon, 07 Mar 2016 17:44:04 base_connection.py[line:221] ERROR Connection to ::1:5672 failed: timeout
Mon, 07 Mar 2016 17:44:04 connection.py[line:750] WARNING Could not connect, 0 attempts left
Mon, 07 Mar 2016 17:44:04 callback.py[line:220] DEBUG Processing 0:_on_connection_error
Mon, 07 Mar 2016 17:44:04 callback.py[line:234] DEBUG Calling <bound method TornadoConnection._on_connection_error of <pika.adapters.tornado_connection.TornadoConnection object at 0x0000000004338BA8>> for "0:_on_connection_error"
Mon, 07 Mar 2016 17:44:04 callback.py[line:239] ERROR Calling <bound method TornadoConnection._on_connection_error of <pika.adapters.tornado_connection.TornadoConnection object at 0x0000000004338BA8>> for "0:_on_connection_error" failed
Traceback (most recent call last):
  File "C:\Python27\lib\site-packages\pika\callback.py", line 236, in process
    callback(*args, **keywords)
  File "C:\Python27\lib\site-packages\pika\connection.py", line 1265, in _on_connection_error
    self.params.connection_attempts)
AMQPConnectionError: Connection to ::1:5672 failed: timeout
Mon, 07 Mar 2016 17:44:04 connection.py[line:54] INFO Retrying to connect in 2 seconds
Mon, 07 Mar 2016 17:44:06 callback.py[line:164] DEBUG Added: {'callback': <bound method TornadoConnection._on_connection_error of <pika.adapters.tornado_connection.TornadoConnection object at 0x0000000004338A90>>, 'only': None, 'one_shot': False, 'arguments': None}
Mon, 07 Mar 2016 17:44:06 callback.py[line:164] DEBUG Added: {'callback': <functools.partial object at 0x0000000004345B38>, 'only': None, 'one_shot': False, 'arguments': None}
Mon, 07 Mar 2016 17:44:06 callback.py[line:164] DEBUG Added: {'callback': <functools.partial object at 0x0000000004345AE8>, 'only': None, 'one_shot': False, 'arguments': None}
Mon, 07 Mar 2016 17:44:06 callback.py[line:164] DEBUG Added: {'callback': <bound method TornadoConnection._on_connection_start of <pika.adapters.tornado_connection.TornadoConnection object at 0x0000000004338A90>>, 'only': None, 'one_shot': True, 'arguments': None, 'calls': 1}
Mon, 07 Mar 2016 17:44:06 base_connection.py[line:212] INFO Connecting to 127.0.0.1:5672
Mon, 07 Mar 2016 17:44:06 base_connection.py[line:221] ERROR Connection to 127.0.0.1:5672 failed: timeout
Mon, 07 Mar 2016 17:44:06 base_connection.py[line:212] INFO Connecting to ::1:5672
Mon, 07 Mar 2016 17:44:06 base_connection.py[line:221] ERROR Connection to ::1:5672 failed: timeout
Mon, 07 Mar 2016 17:44:06 connection.py[line:750] WARNING Could not connect, 0 attempts left
Mon, 07 Mar 2016 17:44:06 callback.py[line:220] DEBUG Processing 0:_on_connection_error
Mon, 07 Mar 2016 17:44:06 callback.py[line:234] DEBUG Calling <bound method TornadoConnection._on_connection_error of <pika.adapters.tornado_connection.TornadoConnection object at 0x0000000004338A90>> for "0:_on_connection_error"
Mon, 07 Mar 2016 17:44:06 callback.py[line:239] ERROR Calling <bound method TornadoConnection._on_connection_error of <pika.adapters.tornado_connection.TornadoConnection object at 0x0000000004338A90>> for "0:_on_connection_error" failed
Traceback (most recent call last):
  File "C:\Python27\lib\site-packages\pika\callback.py", line 236, in process
    callback(*args, **keywords)
  File "C:\Python27\lib\site-packages\pika\connection.py", line 1265, in _on_connection_error
    self.params.connection_attempts)
AMQPConnectionError: Connection to ::1:5672 failed: timeout
Mon, 07 Mar 2016 17:44:06 connection.py[line:54] INFO Retrying to connect in 2 seconds
Mon, 07 Mar 2016 17:44:08 callback.py[line:164] DEBUG Added: {'callback': <bound method TornadoConnection._on_connection_error of <pika.adapters.tornado_connection.TornadoConnection object at 0x0000000004338978>>, 'only': None, 'one_shot': False, 'arguments': None}
Mon, 07 Mar 2016 17:44:08 callback.py[line:164] DEBUG Added: {'callback': <functools.partial object at 0x00000000043459A8>, 'only': None, 'one_shot': False, 'arguments': None}
Mon, 07 Mar 2016 17:44:08 callback.py[line:164] DEBUG Added: {'callback': <functools.partial object at 0x0000000004345958>, 'only': None, 'one_shot': False, 'arguments': None}
Mon, 07 Mar 2016 17:44:08 callback.py[line:164] DEBUG Added: {'callback': <bound method TornadoConnection._on_connection_start of <pika.adapters.tornado_connection.TornadoConnection object at 0x0000000004338978>>, 'only': None, 'one_shot': True, 'arguments': None, 'calls': 1}
Mon, 07 Mar 2016 17:44:08 base_connection.py[line:212] INFO Connecting to 127.0.0.1:5672
Mon, 07 Mar 2016 17:44:08 base_connection.py[line:221] ERROR Connection to 127.0.0.1:5672 failed: timeout
Mon, 07 Mar 2016 17:44:08 base_connection.py[line:212] INFO Connecting to ::1:5672
Mon, 07 Mar 2016 17:44:09 base_connection.py[line:221] ERROR Connection to ::1:5672 failed: timeout
Mon, 07 Mar 2016 17:44:09 connection.py[line:750] WARNING Could not connect, 0 attempts left
Mon, 07 Mar 2016 17:44:09 callback.py[line:220] DEBUG Processing 0:_on_connection_error
Mon, 07 Mar 2016 17:44:09 callback.py[line:234] DEBUG Calling <bound method TornadoConnection._on_connection_error of <pika.adapters.tornado_connection.TornadoConnection object at 0x0000000004338978>> for "0:_on_connection_error"
Mon, 07 Mar 2016 17:44:09 callback.py[line:239] ERROR Calling <bound method TornadoConnection._on_connection_error of <pika.adapters.tornado_connection.TornadoConnection object at 0x0000000004338978>> for "0:_on_connection_error" failed
Traceback (most recent call last):
  File "C:\Python27\lib\site-packages\pika\callback.py", line 236, in process
    callback(*args, **keywords)
  File "C:\Python27\lib\site-packages\pika\connection.py", line 1265, in _on_connection_error
    self.params.connection_attempts)
AMQPConnectionError: Connection to ::1:5672 failed: timeout
Mon, 07 Mar 2016 17:44:09 connection.py[line:54] INFO Retrying to connect in 2 seconds
Mon, 07 Mar 2016 17:44:11 callback.py[line:164] DEBUG Added: {'callback': <bound method TornadoConnection._on_connection_error of <pika.adapters.tornado_connection.TornadoConnection object at 0x0000000004338898>>, 'only': None, 'one_shot': False, 'arguments': None}
Mon, 07 Mar 2016 17:44:11 callback.py[line:164] DEBUG Added: {'callback': <functools.partial object at 0x0000000004345908>, 'only': None, 'one_shot': False, 'arguments': None}
Mon, 07 Mar 2016 17:44:11 callback.py[line:164] DEBUG Added: {'callback': <functools.partial object at 0x00000000043458B8>, 'only': None, 'one_shot': False, 'arguments': None}
Mon, 07 Mar 2016 17:44:11 callback.py[line:164] DEBUG Added: {'callback': <bound method TornadoConnection._on_connection_start of <pika.adapters.tornado_connection.TornadoConnection object at 0x0000000004338898>>, 'only': None, 'one_shot': True, 'arguments': None, 'calls': 1}
Mon, 07 Mar 2016 17:44:11 base_connection.py[line:212] INFO Connecting to 127.0.0.1:5672
Mon, 07 Mar 2016 17:44:11 base_connection.py[line:221] ERROR Connection to 127.0.0.1:5672 failed: timeout
Mon, 07 Mar 2016 17:44:11 base_connection.py[line:212] INFO Connecting to ::1:5672
Mon, 07 Mar 2016 17:44:11 base_connection.py[line:221] ERROR Connection to ::1:5672 failed: timeout
Mon, 07 Mar 2016 17:44:11 connection.py[line:750] WARNING Could not connect, 0 attempts left
Mon, 07 Mar 2016 17:44:11 callback.py[line:220] DEBUG Processing 0:_on_connection_error
Mon, 07 Mar 2016 17:44:11 callback.py[line:234] DEBUG Calling <bound method TornadoConnection._on_connection_error of <pika.adapters.tornado_connection.TornadoConnection object at 0x0000000004338898>> for "0:_on_connection_error"
Mon, 07 Mar 2016 17:44:11 callback.py[line:239] ERROR Calling <bound method TornadoConnection._on_connection_error of <pika.adapters.tornado_connection.TornadoConnection object at 0x0000000004338898>> for "0:_on_connection_error" failed
Traceback (most recent call last):
  File "C:\Python27\lib\site-packages\pika\callback.py", line 236, in process
    callback(*args, **keywords)
  File "C:\Python27\lib\site-packages\pika\connection.py", line 1265, in _on_connection_error
    self.params.connection_attempts)
AMQPConnectionError: Connection to ::1:5672 failed: timeout
Mon, 07 Mar 2016 17:44:11 connection.py[line:54] INFO Retrying to connect in 2 seconds
Mon, 07 Mar 2016 17:44:13 callback.py[line:164] DEBUG Added: {'callback': <bound method TornadoConnection._on_connection_error of <pika.adapters.tornado_connection.TornadoConnection object at 0x00000000043387F0>>, 'only': None, 'one_shot': False, 'arguments': None}
Mon, 07 Mar 2016 17:44:13 callback.py[line:164] DEBUG Added: {'callback': <functools.partial object at 0x0000000004345868>, 'only': None, 'one_shot': False, 'arguments': None}
Mon, 07 Mar 2016 17:44:13 callback.py[line:164] DEBUG Added: {'callback': <functools.partial object at 0x0000000004345818>, 'only': None, 'one_shot': False, 'arguments': None}
Mon, 07 Mar 2016 17:44:13 callback.py[line:164] DEBUG Added: {'callback': <bound method TornadoConnection._on_connection_start of <pika.adapters.tornado_connection.TornadoConnection object at 0x00000000043387F0>>, 'only': None, 'one_shot': True, 'arguments': None, 'calls': 1}
Mon, 07 Mar 2016 17:44:13 base_connection.py[line:212] INFO Connecting to 127.0.0.1:5672
Mon, 07 Mar 2016 17:44:14 base_connection.py[line:221] ERROR Connection to 127.0.0.1:5672 failed: timeout
Mon, 07 Mar 2016 17:44:14 base_connection.py[line:212] INFO Connecting to ::1:5672
Mon, 07 Mar 2016 17:44:14 base_connection.py[line:221] ERROR Connection to ::1:5672 failed: timeout
Mon, 07 Mar 2016 17:44:14 connection.py[line:750] WARNING Could not connect, 0 attempts left
Mon, 07 Mar 2016 17:44:14 callback.py[line:220] DEBUG Processing 0:_on_connection_error
Mon, 07 Mar 2016 17:44:14 callback.py[line:234] DEBUG Calling <bound method TornadoConnection._on_connection_error of <pika.adapters.tornado_connection.TornadoConnection object at 0x00000000043387F0>> for "0:_on_connection_error"
Mon, 07 Mar 2016 17:44:14 callback.py[line:239] ERROR Calling <bound method TornadoConnection._on_connection_error of <pika.adapters.tornado_connection.TornadoConnection object at 0x00000000043387F0>> for "0:_on_connection_error" failed
Traceback (most recent call last):
  File "C:\Python27\lib\site-packages\pika\callback.py", line 236, in process
    callback(*args, **keywords)
  File "C:\Python27\lib\site-packages\pika\connection.py", line 1265, in _on_connection_error
    self.params.connection_attempts)
AMQPConnectionError: Connection to ::1:5672 failed: timeout
Mon, 07 Mar 2016 17:44:14 connection.py[line:54] INFO Retrying to connect in 2 seconds
Mon, 07 Mar 2016 17:44:16 callback.py[line:164] DEBUG Added: {'callback': <bound method TornadoConnection._on_connection_error of <pika.adapters.tornado_connection.TornadoConnection object at 0x0000000004338F28>>, 'only': None, 'one_shot': False, 'arguments': None}
Mon, 07 Mar 2016 17:44:16 callback.py[line:164] DEBUG Added: {'callback': <functools.partial object at 0x00000000043457C8>, 'only': None, 'one_shot': False, 'arguments': None}
Mon, 07 Mar 2016 17:44:16 callback.py[line:164] DEBUG Added: {'callback': <functools.partial object at 0x0000000004345688>, 'only': None, 'one_shot': False, 'arguments': None}
Mon, 07 Mar 2016 17:44:16 callback.py[line:164] DEBUG Added: {'callback': <bound method TornadoConnection._on_connection_start of <pika.adapters.tornado_connection.TornadoConnection object at 0x0000000004338F28>>, 'only': None, 'one_shot': True, 'arguments': None, 'calls': 1}
Mon, 07 Mar 2016 17:44:16 base_connection.py[line:212] INFO Connecting to 127.0.0.1:5672
Mon, 07 Mar 2016 17:44:16 base_connection.py[line:221] ERROR Connection to 127.0.0.1:5672 failed: timeout
Mon, 07 Mar 2016 17:44:16 base_connection.py[line:212] INFO Connecting to ::1:5672
Mon, 07 Mar 2016 17:44:16 base_connection.py[line:221] ERROR Connection to ::1:5672 failed: timeout
Mon, 07 Mar 2016 17:44:16 connection.py[line:750] WARNING Could not connect, 0 attempts left
Mon, 07 Mar 2016 17:44:16 callback.py[line:220] DEBUG Processing 0:_on_connection_error
Mon, 07 Mar 2016 17:44:16 callback.py[line:234] DEBUG Calling <bound method TornadoConnection._on_connection_error of <pika.adapters.tornado_connection.TornadoConnection object at 0x0000000004338F28>> for "0:_on_connection_error"
Mon, 07 Mar 2016 17:44:16 callback.py[line:239] ERROR Calling <bound method TornadoConnection._on_connection_error of <pika.adapters.tornado_connection.TornadoConnection object at 0x0000000004338F28>> for "0:_on_connection_error" failed
Traceback (most recent call last):
  File "C:\Python27\lib\site-packages\pika\callback.py", line 236, in process
    callback(*args, **keywords)
  File "C:\Python27\lib\site-packages\pika\connection.py", line 1265, in _on_connection_error
    self.params.connection_attempts)
AMQPConnectionError: Connection to ::1:5672 failed: timeout
Mon, 07 Mar 2016 17:44:16 connection.py[line:54] INFO Retrying to connect in 2 seconds
Mon, 07 Mar 2016 17:44:18 callback.py[line:164] DEBUG Added: {'callback': <bound method TornadoConnection._on_connection_error of <pika.adapters.tornado_connection.TornadoConnection object at 0x00000000043500F0>>, 'only': None, 'one_shot': False, 'arguments': None}
Mon, 07 Mar 2016 17:44:18 callback.py[line:164] DEBUG Added: {'callback': <functools.partial object at 0x00000000043456D8>, 'only': None, 'one_shot': False, 'arguments': None}
Mon, 07 Mar 2016 17:44:18 callback.py[line:164] DEBUG Added: {'callback': <functools.partial object at 0x0000000004345B88>, 'only': None, 'one_shot': False, 'arguments': None}
Mon, 07 Mar 2016 17:44:18 callback.py[line:164] DEBUG Added: {'callback': <bound method TornadoConnection._on_connection_start of <pika.adapters.tornado_connection.TornadoConnection object at 0x00000000043500F0>>, 'only': None, 'one_shot': True, 'arguments': None, 'calls': 1}
Mon, 07 Mar 2016 17:44:18 base_connection.py[line:212] INFO Connecting to 127.0.0.1:5672
Mon, 07 Mar 2016 17:44:19 base_connection.py[line:221] ERROR Connection to 127.0.0.1:5672 failed: timeout
Mon, 07 Mar 2016 17:44:19 base_connection.py[line:212] INFO Connecting to ::1:5672
Mon, 07 Mar 2016 17:44:19 base_connection.py[line:221] ERROR Connection to ::1:5672 failed: timeout
Mon, 07 Mar 2016 17:44:19 connection.py[line:750] WARNING Could not connect, 0 attempts left
Mon, 07 Mar 2016 17:44:19 callback.py[line:220] DEBUG Processing 0:_on_connection_error
Mon, 07 Mar 2016 17:44:19 callback.py[line:234] DEBUG Calling <bound method TornadoConnection._on_connection_error of <pika.adapters.tornado_connection.TornadoConnection object at 0x00000000043500F0>> for "0:_on_connection_error"
Mon, 07 Mar 2016 17:44:19 callback.py[line:239] ERROR Calling <bound method TornadoConnection._on_connection_error of <pika.adapters.tornado_connection.TornadoConnection object at 0x00000000043500F0>> for "0:_on_connection_error" failed
Traceback (most recent call last):
  File "C:\Python27\lib\site-packages\pika\callback.py", line 236, in process
    callback(*args, **keywords)
  File "C:\Python27\lib\site-packages\pika\connection.py", line 1265, in _on_connection_error
    self.params.connection_attempts)
AMQPConnectionError: Connection to ::1:5672 failed: timeout
Mon, 07 Mar 2016 17:44:19 connection.py[line:54] INFO Retrying to connect in 2 seconds
Mon, 07 Mar 2016 17:44:21 callback.py[line:164] DEBUG Added: {'callback': <bound method TornadoConnection._on_connection_error of <pika.adapters.tornado_connection.TornadoConnection object at 0x0000000004350208>>, 'only': None, 'one_shot': False, 'arguments': None}
Mon, 07 Mar 2016 17:44:21 callback.py[line:164] DEBUG Added: {'callback': <functools.partial object at 0x0000000004345BD8>, 'only': None, 'one_shot': False, 'arguments': None}
Mon, 07 Mar 2016 17:44:21 callback.py[line:164] DEBUG Added: {'callback': <functools.partial object at 0x0000000004345C28>, 'only': None, 'one_shot': False, 'arguments': None}
Mon, 07 Mar 2016 17:44:21 callback.py[line:164] DEBUG Added: {'callback': <bound method TornadoConnection._on_connection_start of <pika.adapters.tornado_connection.TornadoConnection object at 0x0000000004350208>>, 'only': None, 'one_shot': True, 'arguments': None, 'calls': 1}
Mon, 07 Mar 2016 17:44:21 base_connection.py[line:212] INFO Connecting to 127.0.0.1:5672
Mon, 07 Mar 2016 17:44:21 base_connection.py[line:221] ERROR Connection to 127.0.0.1:5672 failed: timeout
Mon, 07 Mar 2016 17:44:21 base_connection.py[line:212] INFO Connecting to ::1:5672
Mon, 07 Mar 2016 17:44:21 base_connection.py[line:221] ERROR Connection to ::1:5672 failed: timeout
Mon, 07 Mar 2016 17:44:21 connection.py[line:750] WARNING Could not connect, 0 attempts left
Mon, 07 Mar 2016 17:44:21 callback.py[line:220] DEBUG Processing 0:_on_connection_error
Mon, 07 Mar 2016 17:44:21 callback.py[line:234] DEBUG Calling <bound method TornadoConnection._on_connection_error of <pika.adapters.tornado_connection.TornadoConnection object at 0x0000000004350208>> for "0:_on_connection_error"
Mon, 07 Mar 2016 17:44:21 callback.py[line:239] ERROR Calling <bound method TornadoConnection._on_connection_error of <pika.adapters.tornado_connection.TornadoConnection object at 0x0000000004350208>> for "0:_on_connection_error" failed
Traceback (most recent call last):
  File "C:\Python27\lib\site-packages\pika\callback.py", line 236, in process
    callback(*args, **keywords)
  File "C:\Python27\lib\site-packages\pika\connection.py", line 1265, in _on_connection_error
    self.params.connection_attempts)
AMQPConnectionError: Connection to ::1:5672 failed: timeout
Mon, 07 Mar 2016 17:44:21 connection.py[line:54] INFO Retrying to connect in 2 seconds
Mon, 07 Mar 2016 17:44:23 callback.py[line:164] DEBUG Added: {'callback': <bound method TornadoConnection._on_connection_error of <pika.adapters.tornado_connection.TornadoConnection object at 0x0000000004350320>>, 'only': None, 'one_shot': False, 'arguments': None}
Mon, 07 Mar 2016 17:44:23 callback.py[line:164] DEBUG Added: {'callback': <functools.partial object at 0x0000000004345C78>, 'only': None, 'one_shot': False, 'arguments': None}
Mon, 07 Mar 2016 17:44:23 callback.py[line:164] DEBUG Added: {'callback': <functools.partial object at 0x0000000004345CC8>, 'only': None, 'one_shot': False, 'arguments': None}
Mon, 07 Mar 2016 17:44:23 callback.py[line:164] DEBUG Added: {'callback': <bound method TornadoConnection._on_connection_start of <pika.adapters.tornado_connection.TornadoConnection object at 0x0000000004350320>>, 'only': None, 'one_shot': True, 'arguments': None, 'calls': 1}
Mon, 07 Mar 2016 17:44:23 base_connection.py[line:212] INFO Connecting to 127.0.0.1:5672
Mon, 07 Mar 2016 17:44:24 base_connection.py[line:221] ERROR Connection to 127.0.0.1:5672 failed: timeout
Mon, 07 Mar 2016 17:44:24 base_connection.py[line:212] INFO Connecting to ::1:5672
Mon, 07 Mar 2016 17:44:24 base_connection.py[line:221] ERROR Connection to ::1:5672 failed: timeout
Mon, 07 Mar 2016 17:44:24 connection.py[line:750] WARNING Could not connect, 0 attempts left
Mon, 07 Mar 2016 17:44:24 callback.py[line:220] DEBUG Processing 0:_on_connection_error
Mon, 07 Mar 2016 17:44:24 callback.py[line:234] DEBUG Calling <bound method TornadoConnection._on_connection_error of <pika.adapters.tornado_connection.TornadoConnection object at 0x0000000004350320>> for "0:_on_connection_error"
Mon, 07 Mar 2016 17:44:24 callback.py[line:239] ERROR Calling <bound method TornadoConnection._on_connection_error of <pika.adapters.tornado_connection.TornadoConnection object at 0x0000000004350320>> for "0:_on_connection_error" failed
Traceback (most recent call last):
  File "C:\Python27\lib\site-packages\pika\callback.py", line 236, in process
    callback(*args, **keywords)
  File "C:\Python27\lib\site-packages\pika\connection.py", line 1265, in _on_connection_error
    self.params.connection_attempts)
AMQPConnectionError: Connection to ::1:5672 failed: timeout
Mon, 07 Mar 2016 17:44:24 connection.py[line:54] INFO Retrying to connect in 2 seconds
Mon, 07 Mar 2016 17:44:26 callback.py[line:164] DEBUG Added: {'callback': <bound method TornadoConnection._on_connection_error of <pika.adapters.tornado_connection.TornadoConnection object at 0x0000000004350438>>, 'only': None, 'one_shot': False, 'arguments': None}
Mon, 07 Mar 2016 17:44:26 callback.py[line:164] DEBUG Added: {'callback': <functools.partial object at 0x0000000004345D18>, 'only': None, 'one_shot': False, 'arguments': None}
Mon, 07 Mar 2016 17:44:26 callback.py[line:164] DEBUG Added: {'callback': <functools.partial object at 0x0000000004345D68>, 'only': None, 'one_shot': False, 'arguments': None}
Mon, 07 Mar 2016 17:44:26 callback.py[line:164] DEBUG Added: {'callback': <bound method TornadoConnection._on_connection_start of <pika.adapters.tornado_connection.TornadoConnection object at 0x0000000004350438>>, 'only': None, 'one_shot': True, 'arguments': None, 'calls': 1}
Mon, 07 Mar 2016 17:44:26 base_connection.py[line:212] INFO Connecting to 127.0.0.1:5672
Mon, 07 Mar 2016 17:44:26 base_connection.py[line:221] ERROR Connection to 127.0.0.1:5672 failed: timeout
Mon, 07 Mar 2016 17:44:26 base_connection.py[line:212] INFO Connecting to ::1:5672
Mon, 07 Mar 2016 17:44:26 base_connection.py[line:221] ERROR Connection to ::1:5672 failed: timeout
Mon, 07 Mar 2016 17:44:26 connection.py[line:750] WARNING Could not connect, 0 attempts left
Mon, 07 Mar 2016 17:44:26 callback.py[line:220] DEBUG Processing 0:_on_connection_error
Mon, 07 Mar 2016 17:44:26 callback.py[line:234] DEBUG Calling <bound method TornadoConnection._on_connection_error of <pika.adapters.tornado_connection.TornadoConnection object at 0x0000000004350438>> for "0:_on_connection_error"
Mon, 07 Mar 2016 17:44:26 callback.py[line:239] ERROR Calling <bound method TornadoConnection._on_connection_error of <pika.adapters.tornado_connection.TornadoConnection object at 0x0000000004350438>> for "0:_on_connection_error" failed
Traceback (most recent call last):
  File "C:\Python27\lib\site-packages\pika\callback.py", line 236, in process
    callback(*args, **keywords)
  File "C:\Python27\lib\site-packages\pika\connection.py", line 1265, in _on_connection_error
    self.params.connection_attempts)
AMQPConnectionError: Connection to ::1:5672 failed: timeout
Mon, 07 Mar 2016 17:44:26 connection.py[line:54] INFO Retrying to connect in 2 seconds
Mon, 07 Mar 2016 17:44:28 callback.py[line:164] DEBUG Added: {'callback': <bound method TornadoConnection._on_connection_error of <pika.adapters.tornado_connection.TornadoConnection object at 0x0000000004350550>>, 'only': None, 'one_shot': False, 'arguments': None}
Mon, 07 Mar 2016 17:44:28 callback.py[line:164] DEBUG Added: {'callback': <functools.partial object at 0x0000000004345DB8>, 'only': None, 'one_shot': False, 'arguments': None}
Mon, 07 Mar 2016 17:44:28 callback.py[line:164] DEBUG Added: {'callback': <functools.partial object at 0x0000000004345E08>, 'only': None, 'one_shot': False, 'arguments': None}
Mon, 07 Mar 2016 17:44:28 callback.py[line:164] DEBUG Added: {'callback': <bound method TornadoConnection._on_connection_start of <pika.adapters.tornado_connection.TornadoConnection object at 0x0000000004350550>>, 'only': None, 'one_shot': True, 'arguments': None, 'calls': 1}
Mon, 07 Mar 2016 17:44:28 base_connection.py[line:212] INFO Connecting to 127.0.0.1:5672
Mon, 07 Mar 2016 17:44:29 base_connection.py[line:221] ERROR Connection to 127.0.0.1:5672 failed: timeout
Mon, 07 Mar 2016 17:44:29 base_connection.py[line:212] INFO Connecting to ::1:5672
Mon, 07 Mar 2016 17:44:29 base_connection.py[line:221] ERROR Connection to ::1:5672 failed: timeout
Mon, 07 Mar 2016 17:44:29 connection.py[line:750] WARNING Could not connect, 0 attempts left
Mon, 07 Mar 2016 17:44:29 callback.py[line:220] DEBUG Processing 0:_on_connection_error
Mon, 07 Mar 2016 17:44:29 callback.py[line:234] DEBUG Calling <bound method TornadoConnection._on_connection_error of <pika.adapters.tornado_connection.TornadoConnection object at 0x0000000004350550>> for "0:_on_connection_error"
Mon, 07 Mar 2016 17:44:29 callback.py[line:239] ERROR Calling <bound method TornadoConnection._on_connection_error of <pika.adapters.tornado_connection.TornadoConnection object at 0x0000000004350550>> for "0:_on_connection_error" failed
Traceback (most recent call last):
  File "C:\Python27\lib\site-packages\pika\callback.py", line 236, in process
    callback(*args, **keywords)
  File "C:\Python27\lib\site-packages\pika\connection.py", line 1265, in _on_connection_error
    self.params.connection_attempts)
AMQPConnectionError: Connection to ::1:5672 failed: timeout
Mon, 07 Mar 2016 17:44:29 connection.py[line:54] INFO Retrying to connect in 2 seconds
Mon, 07 Mar 2016 17:44:31 callback.py[line:164] DEBUG Added: {'callback': <bound method TornadoConnection._on_connection_error of <pika.adapters.tornado_connection.TornadoConnection object at 0x00000000043505C0>>, 'only': None, 'one_shot': False, 'arguments': None}
Mon, 07 Mar 2016 17:44:31 callback.py[line:164] DEBUG Added: {'callback': <functools.partial object at 0x0000000004363098>, 'only': None, 'one_shot': False, 'arguments': None}
Mon, 07 Mar 2016 17:44:31 callback.py[line:164] DEBUG Added: {'callback': <functools.partial object at 0x00000000043B6368>, 'only': None, 'one_shot': False, 'arguments': None}
Mon, 07 Mar 2016 17:44:31 callback.py[line:164] DEBUG Added: {'callback': <bound method TornadoConnection._on_connection_start of <pika.adapters.tornado_connection.TornadoConnection object at 0x00000000043505C0>>, 'only': None, 'one_shot': True, 'arguments': None, 'calls': 1}
Mon, 07 Mar 2016 17:44:31 base_connection.py[line:212] INFO Connecting to 127.0.0.1:5672
Mon, 07 Mar 2016 17:44:31 base_connection.py[line:221] ERROR Connection to 127.0.0.1:5672 failed: timeout
Mon, 07 Mar 2016 17:44:31 base_connection.py[line:212] INFO Connecting to ::1:5672
Mon, 07 Mar 2016 17:44:31 base_connection.py[line:221] ERROR Connection to ::1:5672 failed: timeout
Mon, 07 Mar 2016 17:44:31 connection.py[line:750] WARNING Could not connect, 0 attempts left
Mon, 07 Mar 2016 17:44:31 callback.py[line:220] DEBUG Processing 0:_on_connection_error
Mon, 07 Mar 2016 17:44:31 callback.py[line:234] DEBUG Calling <bound method TornadoConnection._on_connection_error of <pika.adapters.tornado_connection.TornadoConnection object at 0x00000000043505C0>> for "0:_on_connection_error"
Mon, 07 Mar 2016 17:44:31 callback.py[line:239] ERROR Calling <bound method TornadoConnection._on_connection_error of <pika.adapters.tornado_connection.TornadoConnection object at 0x00000000043505C0>> for "0:_on_connection_error" failed
Traceback (most recent call last):
  File "C:\Python27\lib\site-packages\pika\callback.py", line 236, in process
    callback(*args, **keywords)
  File "C:\Python27\lib\site-packages\pika\connection.py", line 1265, in _on_connection_error
    self.params.connection_attempts)
AMQPConnectionError: Connection to ::1:5672 failed: timeout
Mon, 07 Mar 2016 17:44:31 connection.py[line:54] INFO Retrying to connect in 2 seconds
Mon, 07 Mar 2016 17:44:33 callback.py[line:164] DEBUG Added: {'callback': <bound method TornadoConnection._on_connection_error of <pika.adapters.tornado_connection.TornadoConnection object at 0x0000000004338B00>>, 'only': None, 'one_shot': False, 'arguments': None}
Mon, 07 Mar 2016 17:44:33 callback.py[line:164] DEBUG Added: {'callback': <functools.partial object at 0x0000000004345EF8>, 'only': None, 'one_shot': False, 'arguments': None}
Mon, 07 Mar 2016 17:44:33 callback.py[line:164] DEBUG Added: {'callback': <functools.partial object at 0x0000000004345D68>, 'only': None, 'one_shot': False, 'arguments': None}
Mon, 07 Mar 2016 17:44:33 callback.py[line:164] DEBUG Added: {'callback': <bound method TornadoConnection._on_connection_start of <pika.adapters.tornado_connection.TornadoConnection object at 0x0000000004338B00>>, 'only': None, 'one_shot': True, 'arguments': None, 'calls': 1}
Mon, 07 Mar 2016 17:44:33 base_connection.py[line:212] INFO Connecting to 127.0.0.1:5672
Mon, 07 Mar 2016 17:44:34 base_connection.py[line:221] ERROR Connection to 127.0.0.1:5672 failed: timeout
Mon, 07 Mar 2016 17:44:34 base_connection.py[line:212] INFO Connecting to ::1:5672
Mon, 07 Mar 2016 17:44:34 base_connection.py[line:221] ERROR Connection to ::1:5672 failed: timeout
Mon, 07 Mar 2016 17:44:34 connection.py[line:750] WARNING Could not connect, 0 attempts left
Mon, 07 Mar 2016 17:44:34 callback.py[line:220] DEBUG Processing 0:_on_connection_error
Mon, 07 Mar 2016 17:44:34 callback.py[line:234] DEBUG Calling <bound method TornadoConnection._on_connection_error of <pika.adapters.tornado_connection.TornadoConnection object at 0x0000000004338B00>> for "0:_on_connection_error"
Mon, 07 Mar 2016 17:44:34 callback.py[line:239] ERROR Calling <bound method TornadoConnection._on_connection_error of <pika.adapters.tornado_connection.TornadoConnection object at 0x0000000004338B00>> for "0:_on_connection_error" failed
Traceback (most recent call last):
  File "C:\Python27\lib\site-packages\pika\callback.py", line 236, in process
    callback(*args, **keywords)
  File "C:\Python27\lib\site-packages\pika\connection.py", line 1265, in _on_connection_error
    self.params.connection_attempts)
AMQPConnectionError: Connection to ::1:5672 failed: timeout
Mon, 07 Mar 2016 17:44:34 connection.py[line:54] INFO Retrying to connect in 2 seconds
Mon, 07 Mar 2016 17:44:36 callback.py[line:164] DEBUG Added: {'callback': <bound method TornadoConnection._on_connection_error of <pika.adapters.tornado_connection.TornadoConnection object at 0x0000000004338C88>>, 'only': None, 'one_shot': False, 'arguments': None}
Mon, 07 Mar 2016 17:44:36 callback.py[line:164] DEBUG Added: {'callback': <functools.partial object at 0x0000000004345F48>, 'only': None, 'one_shot': False, 'arguments': None}
Mon, 07 Mar 2016 17:44:36 callback.py[line:164] DEBUG Added: {'callback': <functools.partial object at 0x0000000004345E08>, 'only': None, 'one_shot': False, 'arguments': None}
Mon, 07 Mar 2016 17:44:36 callback.py[line:164] DEBUG Added: {'callback': <bound method TornadoConnection._on_connection_start of <pika.adapters.tornado_connection.TornadoConnection object at 0x0000000004338C88>>, 'only': None, 'one_shot': True, 'arguments': None, 'calls': 1}
Mon, 07 Mar 2016 17:44:36 base_connection.py[line:212] INFO Connecting to 127.0.0.1:5672
Mon, 07 Mar 2016 17:44:36 base_connection.py[line:221] ERROR Connection to 127.0.0.1:5672 failed: timeout
Mon, 07 Mar 2016 17:44:36 base_connection.py[line:212] INFO Connecting to ::1:5672
Mon, 07 Mar 2016 17:44:36 base_connection.py[line:221] ERROR Connection to ::1:5672 failed: timeout
Mon, 07 Mar 2016 17:44:36 connection.py[line:750] WARNING Could not connect, 0 attempts left
Mon, 07 Mar 2016 17:44:36 callback.py[line:220] DEBUG Processing 0:_on_connection_error
Mon, 07 Mar 2016 17:44:36 callback.py[line:234] DEBUG Calling <bound method TornadoConnection._on_connection_error of <pika.adapters.tornado_connection.TornadoConnection object at 0x0000000004338C88>> for "0:_on_connection_error"
Mon, 07 Mar 2016 17:44:36 callback.py[line:239] ERROR Calling <bound method TornadoConnection._on_connection_error of <pika.adapters.tornado_connection.TornadoConnection object at 0x0000000004338C88>> for "0:_on_connection_error" failed
Traceback (most recent call last):
  File "C:\Python27\lib\site-packages\pika\callback.py", line 236, in process
    callback(*args, **keywords)
  File "C:\Python27\lib\site-packages\pika\connection.py", line 1265, in _on_connection_error
    self.params.connection_attempts)
AMQPConnectionError: Connection to ::1:5672 failed: timeout
Mon, 07 Mar 2016 17:44:36 connection.py[line:54] INFO Retrying to connect in 2 seconds
Mon, 07 Mar 2016 17:44:38 callback.py[line:164] DEBUG Added: {'callback': <bound method TornadoConnection._on_connection_error of <pika.adapters.tornado_connection.TornadoConnection object at 0x00000000042EC4A8>>, 'only': None, 'one_shot': False, 'arguments': None}
Mon, 07 Mar 2016 17:44:38 callback.py[line:164] DEBUG Added: {'callback': <functools.partial object at 0x0000000004345DB8>, 'only': None, 'one_shot': False, 'arguments': None}
Mon, 07 Mar 2016 17:44:38 callback.py[line:164] DEBUG Added: {'callback': <functools.partial object at 0x0000000004345D18>, 'only': None, 'one_shot': False, 'arguments': None}
Mon, 07 Mar 2016 17:44:38 callback.py[line:164] DEBUG Added: {'callback': <bound method TornadoConnection._on_connection_start of <pika.adapters.tornado_connection.TornadoConnection object at 0x00000000042EC4A8>>, 'only': None, 'one_shot': True, 'arguments': None, 'calls': 1}
Mon, 07 Mar 2016 17:44:38 base_connection.py[line:212] INFO Connecting to 127.0.0.1:5672
Mon, 07 Mar 2016 17:44:39 base_connection.py[line:221] ERROR Connection to 127.0.0.1:5672 failed: timeout
Mon, 07 Mar 2016 17:44:39 base_connection.py[line:212] INFO Connecting to ::1:5672
Mon, 07 Mar 2016 17:44:39 base_connection.py[line:221] ERROR Connection to ::1:5672 failed: timeout
Mon, 07 Mar 2016 17:44:39 connection.py[line:750] WARNING Could not connect, 0 attempts left
Mon, 07 Mar 2016 17:44:39 callback.py[line:220] DEBUG Processing 0:_on_connection_error
Mon, 07 Mar 2016 17:44:39 callback.py[line:234] DEBUG Calling <bound method TornadoConnection._on_connection_error of <pika.adapters.tornado_connection.TornadoConnection object at 0x00000000042EC4A8>> for "0:_on_connection_error"
Mon, 07 Mar 2016 17:44:39 callback.py[line:239] ERROR Calling <bound method TornadoConnection._on_connection_error of <pika.adapters.tornado_connection.TornadoConnection object at 0x00000000042EC4A8>> for "0:_on_connection_error" failed
Traceback (most recent call last):
  File "C:\Python27\lib\site-packages\pika\callback.py", line 236, in process
    callback(*args, **keywords)
  File "C:\Python27\lib\site-packages\pika\connection.py", line 1265, in _on_connection_error
    self.params.connection_attempts)
AMQPConnectionError: Connection to ::1:5672 failed: timeout
Mon, 07 Mar 2016 17:44:39 connection.py[line:54] INFO Retrying to connect in 2 seconds
Mon, 07 Mar 2016 18:03:50 callback.py[line:164] DEBUG Added: {'callback': <bound method TornadoConnection._on_connection_error of <pika.adapters.tornado_connection.TornadoConnection object at 0x0000000004474CF8>>, 'only': None, 'one_shot': False, 'arguments': None}
Mon, 07 Mar 2016 18:03:50 callback.py[line:164] DEBUG Added: {'callback': <functools.partial object at 0x0000000004425C28>, 'only': None, 'one_shot': False, 'arguments': None}
Mon, 07 Mar 2016 18:03:50 callback.py[line:164] DEBUG Added: {'callback': <functools.partial object at 0x0000000004425C78>, 'only': None, 'one_shot': False, 'arguments': None}
Mon, 07 Mar 2016 18:03:50 callback.py[line:164] DEBUG Added: {'callback': <bound method TornadoConnection._on_connection_start of <pika.adapters.tornado_connection.TornadoConnection object at 0x0000000004474CF8>>, 'only': None, 'one_shot': True, 'arguments': None, 'calls': 1}
Mon, 07 Mar 2016 18:03:50 base_connection.py[line:212] INFO Connecting to 127.0.0.1:6379
Mon, 07 Mar 2016 18:05:41 callback.py[line:164] DEBUG Added: {'callback': <bound method TornadoConnection._on_connection_error of <pika.adapters.tornado_connection.TornadoConnection object at 0x000000000424CCF8>>, 'only': None, 'one_shot': False, 'arguments': None}
Mon, 07 Mar 2016 18:05:41 callback.py[line:164] DEBUG Added: {'callback': <functools.partial object at 0x00000000041DBC28>, 'only': None, 'one_shot': False, 'arguments': None}
Mon, 07 Mar 2016 18:05:41 callback.py[line:164] DEBUG Added: {'callback': <functools.partial object at 0x00000000041DBC78>, 'only': None, 'one_shot': False, 'arguments': None}
Mon, 07 Mar 2016 18:05:41 callback.py[line:164] DEBUG Added: {'callback': <bound method TornadoConnection._on_connection_start of <pika.adapters.tornado_connection.TornadoConnection object at 0x000000000424CCF8>>, 'only': None, 'one_shot': True, 'arguments': None, 'calls': 1}
Mon, 07 Mar 2016 18:05:41 base_connection.py[line:212] INFO Connecting to 127.0.0.1:6379
Mon, 07 Mar 2016 18:06:08 callback.py[line:164] DEBUG Added: {'callback': <bound method TornadoConnection._on_connection_error of <pika.adapters.tornado_connection.TornadoConnection object at 0x0000000004601CF8>>, 'only': None, 'one_shot': False, 'arguments': None}
Mon, 07 Mar 2016 18:06:08 callback.py[line:164] DEBUG Added: {'callback': <functools.partial object at 0x0000000004581C78>, 'only': None, 'one_shot': False, 'arguments': None}
Mon, 07 Mar 2016 18:06:08 callback.py[line:164] DEBUG Added: {'callback': <functools.partial object at 0x0000000004581CC8>, 'only': None, 'one_shot': False, 'arguments': None}
Mon, 07 Mar 2016 18:06:08 callback.py[line:164] DEBUG Added: {'callback': <bound method TornadoConnection._on_connection_start of <pika.adapters.tornado_connection.TornadoConnection object at 0x0000000004601CF8>>, 'only': None, 'one_shot': True, 'arguments': None, 'calls': 1}
Mon, 07 Mar 2016 18:06:08 base_connection.py[line:212] INFO Connecting to 127.0.0.1:6379
Mon, 07 Mar 2016 18:06:19 callback.py[line:164] DEBUG Added: {'callback': <bound method TornadoConnection._on_connection_error of <pika.adapters.tornado_connection.TornadoConnection object at 0x0000000004484CF8>>, 'only': None, 'one_shot': False, 'arguments': None}
Mon, 07 Mar 2016 18:06:19 callback.py[line:164] DEBUG Added: {'callback': <functools.partial object at 0x0000000004436C78>, 'only': None, 'one_shot': False, 'arguments': None}
Mon, 07 Mar 2016 18:06:19 callback.py[line:164] DEBUG Added: {'callback': <functools.partial object at 0x0000000004436CC8>, 'only': None, 'one_shot': False, 'arguments': None}
Mon, 07 Mar 2016 18:06:19 callback.py[line:164] DEBUG Added: {'callback': <bound method TornadoConnection._on_connection_start of <pika.adapters.tornado_connection.TornadoConnection object at 0x0000000004484CF8>>, 'only': None, 'one_shot': True, 'arguments': None, 'calls': 1}
Mon, 07 Mar 2016 18:06:19 base_connection.py[line:212] INFO Connecting to 127.0.0.1:6379
Mon, 07 Mar 2016 18:22:42 callback.py[line:164] DEBUG Added: {'callback': <bound method TornadoConnection._on_connection_error of <pika.adapters.tornado_connection.TornadoConnection object at 0x00000000043A2CF8>>, 'only': None, 'one_shot': False, 'arguments': None}
Mon, 07 Mar 2016 18:22:42 callback.py[line:164] DEBUG Added: {'callback': <functools.partial object at 0x0000000004343C78>, 'only': None, 'one_shot': False, 'arguments': None}
Mon, 07 Mar 2016 18:22:42 callback.py[line:164] DEBUG Added: {'callback': <functools.partial object at 0x0000000004343CC8>, 'only': None, 'one_shot': False, 'arguments': None}
Mon, 07 Mar 2016 18:22:42 callback.py[line:164] DEBUG Added: {'callback': <bound method TornadoConnection._on_connection_start of <pika.adapters.tornado_connection.TornadoConnection object at 0x00000000043A2CF8>>, 'only': None, 'one_shot': True, 'arguments': None, 'calls': 1}
Mon, 07 Mar 2016 18:22:42 base_connection.py[line:212] INFO Connecting to 127.0.0.1:6379
Mon, 07 Mar 2016 18:29:06 callback.py[line:164] DEBUG Added: {'callback': <bound method TornadoConnection._on_connection_error of <pika.adapters.tornado_connection.TornadoConnection object at 0x000000000437DCF8>>, 'only': None, 'one_shot': False, 'arguments': None}
Mon, 07 Mar 2016 18:29:06 callback.py[line:164] DEBUG Added: {'callback': <functools.partial object at 0x00000000042EBC78>, 'only': None, 'one_shot': False, 'arguments': None}
Mon, 07 Mar 2016 18:29:06 callback.py[line:164] DEBUG Added: {'callback': <functools.partial object at 0x00000000042EBCC8>, 'only': None, 'one_shot': False, 'arguments': None}
Mon, 07 Mar 2016 18:29:06 callback.py[line:164] DEBUG Added: {'callback': <bound method TornadoConnection._on_connection_start of <pika.adapters.tornado_connection.TornadoConnection object at 0x000000000437DCF8>>, 'only': None, 'one_shot': True, 'arguments': None, 'calls': 1}
Mon, 07 Mar 2016 18:29:06 base_connection.py[line:212] INFO Connecting to 127.0.0.1:6379
Mon, 07 Mar 2016 18:34:21 callback.py[line:164] DEBUG Added: {'callback': <bound method TornadoConnection._on_connection_error of <pika.adapters.tornado_connection.TornadoConnection object at 0x000000000442FCF8>>, 'only': None, 'one_shot': False, 'arguments': None}
Mon, 07 Mar 2016 18:34:21 callback.py[line:164] DEBUG Added: {'callback': <functools.partial object at 0x00000000043E0C28>, 'only': None, 'one_shot': False, 'arguments': None}
Mon, 07 Mar 2016 18:34:21 callback.py[line:164] DEBUG Added: {'callback': <functools.partial object at 0x00000000043E0C78>, 'only': None, 'one_shot': False, 'arguments': None}
Mon, 07 Mar 2016 18:34:21 callback.py[line:164] DEBUG Added: {'callback': <bound method TornadoConnection._on_connection_start of <pika.adapters.tornado_connection.TornadoConnection object at 0x000000000442FCF8>>, 'only': None, 'one_shot': True, 'arguments': None, 'calls': 1}
Mon, 07 Mar 2016 18:34:21 base_connection.py[line:212] INFO Connecting to 127.0.0.1:6379
